Traceback (most recent call last):
  File "/home/runner/.cache/pypoetry/virtualenvs/pyfian-xVEnJtcL-py3.12/lib/python3.12/site-packages/jupyter_core/utils/__init__.py", line 154, in wrapped
    asyncio.get_running_loop()
RuntimeError: no running event loop

During handling of the above exception, another exception occurred:

Traceback (most recent call last):
  File "/home/runner/.cache/pypoetry/virtualenvs/pyfian-xVEnJtcL-py3.12/lib/python3.12/site-packages/jupyter_cache/executors/utils.py", line 58, in single_nb_execution
    executenb(
  File "/home/runner/.cache/pypoetry/virtualenvs/pyfian-xVEnJtcL-py3.12/lib/python3.12/site-packages/nbclient/client.py", line 1319, in execute
    return NotebookClient(nb=nb, resources=resources, km=km, **kwargs).execute()
           ^^^^^^^^^^^^^^^^^^^^^^^^^^^^^^^^^^^^^^^^^^^^^^^^^^^^^^^^^^^^^^^^^^^^^
  File "/home/runner/.cache/pypoetry/virtualenvs/pyfian-xVEnJtcL-py3.12/lib/python3.12/site-packages/jupyter_core/utils/__init__.py", line 158, in wrapped
    return loop.run_until_complete(inner)
           ^^^^^^^^^^^^^^^^^^^^^^^^^^^^^^
  File "/opt/hostedtoolcache/Python/3.12.11/x64/lib/python3.12/asyncio/base_events.py", line 691, in run_until_complete
    return future.result()
           ^^^^^^^^^^^^^^^
  File "/home/runner/.cache/pypoetry/virtualenvs/pyfian-xVEnJtcL-py3.12/lib/python3.12/site-packages/nbclient/client.py", line 709, in async_execute
    await self.async_execute_cell(
  File "/home/runner/.cache/pypoetry/virtualenvs/pyfian-xVEnJtcL-py3.12/lib/python3.12/site-packages/nbclient/client.py", line 1062, in async_execute_cell
    await self._check_raise_for_error(cell, cell_index, exec_reply)
  File "/home/runner/.cache/pypoetry/virtualenvs/pyfian-xVEnJtcL-py3.12/lib/python3.12/site-packages/nbclient/client.py", line 918, in _check_raise_for_error
    raise CellExecutionError.from_cell_and_msg(cell, exec_reply_content)
nbclient.exceptions.CellExecutionError: An error occurred while executing the following cell:
------------------
from pyfian.time_value.continuous_compounding import present_value_continuous
from pyfian.time_value.continuous_compounding import future_value_continuous

PV = 100
FV = 200
i = 0.05
t = 1

print(
    f"The present value of a bond with ${FV:,.2f} face value, {i:.2%} interest rate, over {t} year(s) is ${present_value_continuous(FV, i, t):,.2f}"
)
print(
    f"The future value of a bond with ${PV:,.2f} face value, {i:.2%} interest rate, over {t} year(s) is ${future_value_continuous(PV, i, t):,.2f}"
)
------------------


[31m---------------------------------------------------------------------------[39m
[31mModuleNotFoundError[39m                       Traceback (most recent call last)
[36mCell[39m[36m [39m[32mIn[5][39m[32m, line 1[39m
[32m----> [39m[32m1[39m [38;5;28;01mfrom[39;00m[38;5;250m [39m[34;01mpyfian[39;00m[34;01m.[39;00m[34;01mtime_value[39;00m[34;01m.[39;00m[34;01mcontinuous_compounding[39;00m[38;5;250m [39m[38;5;28;01mimport[39;00m present_value_continuous
[32m      2[39m [38;5;28;01mfrom[39;00m[38;5;250m [39m[34;01mpyfian[39;00m[34;01m.[39;00m[34;01mtime_value[39;00m[34;01m.[39;00m[34;01mcontinuous_compounding[39;00m[38;5;250m [39m[38;5;28;01mimport[39;00m future_value_continuous
[32m      4[39m PV = [32m100[39m

[31mModuleNotFoundError[39m: No module named 'pyfian.time_value.continuous_compounding'

